<?xml version="1.0"?>
<robot name="giraffe_robot" xmlns:xacro="http://ros.org/wiki/xacro">

  <!-- ===================== Parameters ===================== -->
  <xacro:property name="pi" value="3.141592653589793"/>
  <xacro:property name="pi_2" value="1.5707963267948966"/>
  <xacro:property name="rho_al" value="2700.0"/>  <!-- aluminum density  [kg/m3] -->

  <!-- Robot Configuration -->
  <!-- Base Link -->
  <xacro:property name="base_radius" value="0.1"/>
  <!-- Shoulder Spherical (2 DOF) -->
  <xacro:property name="shoulder_joint_height" value="0.1"/>
  <xacro:property name="shoulder_joint_radius" value="0.05"/>
  <!-- Arm -->
  <xacro:property name="arm_length" value="2.4"/>
  <xacro:property name="arm_radius" value="0.05"/>
  <!-- Prismatic Extension -->
  <xacro:property name="prismatic_height_delta" value="0.1"/>
  <xacro:property name="prismatic_travel" value="4.0"/>
  <xacro:property name="extend_link_length" value="${prismatic_travel + wrist_radius}"/>
  <!-- Wrist -->
  <xacro:property name="wrist_joint_height" value="0.1"/>
  <xacro:property name="wrist_radius" value="0.025"/>
  <xacro:property name="wrist_link_length" value="1.0"/>
  <!-- Microphone -->
  <xacro:property name="mic_stick_length" value="0.15"/>
  <xacro:property name="mic_stick_radius" value="0.015"/>


  <!-- Mass Computation --> 
  <xacro:property name="shoulder_joint_mass" value="${rho_al * pi * pow(shoulder_joint_radius,2) * shoulder_joint_height}"/>
  <xacro:property name="arm_mass" value="${rho_al * pi * pow(arm_radius,2) * arm_length}"/>
  <xacro:property name="extend_link_mass" value="${rho_al * pi * pow(wrist_radius,2) * extend_link_length}"/>
  <xacro:property name="wrist_link_mass" value="${rho_al * pi * pow(wrist_radius,2) * ( wrist_link_length + (4*wrist_radius) )}"/>
  <xacro:property name="mic_stick_mass" value="${rho_al * pi * pow(mic_stick_radius,2) * mic_stick_length}"/>
  <xacro:property name="mic_mass" value="${rho_al * (4.0/3.0) * pi * pow(mic_stick_radius,3)}"/>

  <!-- ===================== World & Environment ===================== -->
  <link name="world"/>

  <!-- Floor -->
  <link name="floor">
    <visual>
      <geometry>
        <box size="5 12 0.1"/>
      </geometry>
      <origin xyz="0 0 -0.05" rpy="0 0 0"/>
      <material name="gray">
        <color rgba="0.5 0.5 0.5 1"/>
      </material>
    </visual>
  </link> 
  <joint name="floor_fixed" type="fixed">
    <parent link="world"/>
    <child link="floor"/>
    <origin xyz="2.5 6 0" rpy="0 0 0"/>
  </joint>

  <!-- Ceiling -->
  <link name="ceiling">
    <visual>
      <origin xyz="0 0 0.05" rpy="0 0 0"/>
      <geometry>
        <box size="5 12 0.1"/>
      </geometry>
      <material name="ceiling_color">
        <color rgba="0.8 0.8 0.8 1"/>
      </material>
    </visual>
  </link>
  <joint name="ceiling_fixed" type="fixed">
    <parent link="floor"/>
    <child link="ceiling"/>
    <origin xyz="0 0 4" rpy="0 0 0"/>
  </joint>


  <!-- ======== Base Link ======== -->
  <link name="base_link">
    <visual>
      <geometry>
        <cylinder radius="${base_radius}" length="0"/>
      </geometry>
      <origin xyz="0 0 0" rpy="0 0 0"/>
      <material name="red">
        <color rgba="1 0 0 1"/>
      </material>
    </visual>
  </link>
  <joint name="base_link_fixed" type="fixed">
    <parent link="world"/>
    <child link="base_link"/>
    <origin xyz="2.5 6 4" rpy="${pi} 0 -${pi_2}"/>
  </joint>
  
  

  <!-- ======== Shoulder Spherical (2 DOF) ======== -->
  <!-- Revolute joint 1: yaw for sholder -->
  <joint name="shoulder_yaw" type="revolute">
    <parent link="base_link"/>
    <child link="shoulder_link"/>
    <origin xyz="0 0 ${shoulder_joint_height}" rpy="0 0 0"/>
    <axis xyz="0 0 1"/>
    <limit lower="-${pi}" upper="${pi}" effort="50" velocity="1.5"/>
  </joint>

  <!-- Yaw Revolution Joint representation -->
  <link name="shoulder_link">
    <!-- Yaw Revolution Joint representation -->
    <visual>
      <origin xyz="0 0 ${-shoulder_joint_height/2}" rpy="0 0 0"/> 
      <geometry>
        <cylinder length="${shoulder_joint_height}" radius="${shoulder_joint_radius}"/>
      </geometry>
      <material name="blue">
        <color rgba="0.4 0.6 1.0 1"/>
      </material>
    </visual>

    <!-- Pitch Revolution Joint representation -->
    <visual>
      <origin xyz="0 0 0" rpy="-${pi_2} 0 0"/>
      <geometry>
        <cylinder radius="${shoulder_joint_radius}" length="${shoulder_joint_height}"/>
      </geometry>
      <material name="green">
        <color rgba="0.2 0.8 0.2 1.0"/> 
      </material>
    </visual>

    <inertial>
      <origin xyz="0 0 ${-shoulder_joint_height/4}" rpy="0 0 0"/>
      <mass value="${2 * shoulder_joint_mass}"/>
      <inertia
        ixx="${ (1.0/12.0) * shoulder_joint_mass * ( (6*pow(shoulder_joint_radius,2)) + (5*pow(shoulder_joint_height,2) ) ) }"
        iyy="${ (1.0/12.0) * shoulder_joint_mass * ( (9*pow(shoulder_joint_radius,2)) + (4*pow(shoulder_joint_height,2) ) ) }"
        izz="${ (1.0/12.0) * shoulder_joint_mass * ( (9*pow(shoulder_joint_radius,2)) + (pow(shoulder_joint_height,2) ) ) }"
        ixy="0.0"  ixz="0.0"  iyz="0.0"/>
    </inertial>

  </link>

  <!-- Revolute joint 2: pitch for shoulder -->
  <joint name="shoulder_roll" type="revolute">
    <parent link="shoulder_link"/>
    <child link="arm_link"/>
    <!-- rotate frame so its new Z aligns with desired roll axis -->
    <origin rpy="-${pi_2} 0.0 0.0" xyz="0.0 0.0 0.0"/>
    <axis xyz="0 0 1"/>
    <limit effort="150.0" lower="-${pi}" upper="0" velocity="3.15"/>
    <dynamics damping="0.0" friction="0.0"/>
  </joint>


  <!-- ======== Arm ======== -->
  <link name="arm_link"> 
    <!-- Metallic Arm -->
    <visual>
      <origin xyz="${arm_length/2+0.025} 0 0" rpy="0 ${pi_2} 0"/> 
      <geometry>
        <!-- adding shoulder_joint_radius for considering the shoulder width-->
        <cylinder length="${arm_length + shoulder_joint_radius}" radius="${arm_radius}"/>
      </geometry>
      <material name="metal">
        <color rgba="0.6 0.6 0.6 1.0"/>
      </material>
    </visual>

    <!-- Prismatic Joint representation -->
    <visual>
      <origin xyz="${arm_length-0.05} -${prismatic_height_delta} 0" rpy="0 0 0"/> 
      <geometry>
        <box size="0.2 0.1 0.1"/>
      </geometry>
      <material name="orange">
        <color rgba="1 0.5 0 1"/>
      </material>
    </visual>
  
    <inertial>
      <origin xyz="${arm_length/2 + 0.025} 0 0" rpy="0 ${pi_2} 0"/>
      <mass value="${arm_mass}"/>
      <inertia
       ixx="${(1/2.0)*arm_mass*pow(arm_radius,2)}"
       iyy="${(1/12.0)*arm_mass*(3*pow(arm_radius,2)+pow(arm_length,2))}"
       izz="${(1/12.0)*arm_mass*(3*pow(arm_radius,2)+pow(arm_length,2))}"
       ixy="0.0"  ixz="0.0"  iyz="0.0"/>
    </inertial>
  </link>


  <!-- ======== Prismatic Extension ======== -->
  <joint name="prismatic_joint" type="prismatic">
    <parent link="arm_link"/>
    <child link="extend_link"/>
    <axis xyz="0 0 1"/>
    <!-- Adjust wrist radius in order to put the frame in the center of the first wrist joint -->
    <origin xyz="${arm_length + shoulder_joint_radius + wrist_radius} -${prismatic_height_delta} 0" rpy="-${pi_2} 0 -${pi_2}"/>
    <limit effort="50" velocity="0.5" lower="0" upper="${prismatic_travel}"/>
  </joint>

  <link name="extend_link">
    <visual>
      <geometry>
        <cylinder length="${extend_link_length}" radius="${wrist_radius}"/>
      </geometry>
      <origin xyz="0 0 -${extend_link_length / 2}" rpy="0 0 0"/>
      <material name="metal"/>
    </visual>
  
    <inertial>
      <origin xyz="0 0 -${extend_link_length /2}" rpy="0 0 0"/>
      <mass value="${extend_link_mass}"/>
      <inertia
        ixx="${(1.0/12.0) * extend_link_mass * (3 * pow(wrist_radius, 2) + pow(extend_link_length, 2))}"
        iyy="${(1.0/12.0) * extend_link_mass * (3 * pow(wrist_radius, 2) + pow(extend_link_length, 2))}"
        izz="${(1.0/2.0) * extend_link_mass * pow(wrist_radius, 2)}"
        ixy="0.0"  ixz="0.0"  iyz="0.0"/>
    </inertial>
  </link>


  <!-- ======== Wrist Spherical (2 DOF) ======== -->
  <!-- Revolute joint 1: yaw for wrist -->
  <joint name="mic_yaw_joint" type="revolute">
    <parent link="extend_link"/>
    <child link="wrist_link"/>
    <axis xyz="0 0 1"/>
    <origin xyz="0 0 0" rpy="${pi} -${pi_2} 0"/>
    <limit effort="5" velocity="1.0" lower="-1.57" upper="1.57"/>
  </joint>

  <link name="wrist_link">
    <!-- Visuals for the revolute joint 1 -->
    <visual>
      <origin xyz="0 0 0" rpy="0 0 0"/>
      <geometry>
        <cylinder radius="${wrist_radius}" length="${wrist_radius*2}"/>
      </geometry>
      <material name="blue"/>
    </visual>

    <!-- Metallic wrist link -->
    <visual>
      <geometry>
        <cylinder length="${wrist_link_length}" radius="${wrist_radius}"/>
      </geometry>
      <origin xyz="0 0 ${wrist_link_length / 2}" rpy="0 0 0"/>
      <material name="metal"/>
    </visual>

    <!-- Visuals for the mic_yaw_joint link -->
    <visual>
      <origin xyz="0 0 ${wrist_link_length - wrist_radius}" rpy="0 ${pi_2} 0"/>
      <geometry>
        <cylinder radius="${wrist_radius}" length="${wrist_radius*2}"/>
      </geometry>
      <material name="blue"/>
    </visual>

    <inertial>
      <origin xyz="0 0 ${( wrist_link_length +4*wrist_radius ) / 2}" rpy="0 0 0"/>
      <mass value="${wrist_link_mass}"/>
      <inertia
        ixx="${(1.0/12.0) * wrist_link_mass * (3 * pow(wrist_radius, 2) + pow(( wrist_link_length +4*wrist_radius ), 2))}"
        iyy="${(1.0/12.0) * wrist_link_mass * (3 * pow(wrist_radius, 2) + pow(( wrist_link_length +4*wrist_radius ), 2))}"
        izz="${(1.0/2.0) * wrist_link_mass * pow(wrist_radius, 2)}"
        ixy="0.0"  ixz="0.0"  iyz="0.0"/>
    </inertial>
  </link>

  <!-- Revolute joint 2: pitch for microphone -->
  <joint name="mic_pitch_joint" type="revolute">
    <parent link="wrist_link"/>
    <child link="mic_link"/>
    <axis xyz="0 0 1"/>
    <origin xyz="0 0 ${wrist_link_length - wrist_radius}" rpy="-${pi_2} 0 -${pi_2}"/>
    <limit effort="5" velocity="1.0" lower="-3.14" upper="3.14"/>
  </joint>


  <!-- ======== Microphone end-effector ======== -->
  <link name="mic_link">
    <visual>
      <geometry>
        <cylinder length="${mic_stick_length}" radius="${mic_stick_radius}"/>
      </geometry>
      <origin xyz="${(mic_stick_length / 2 ) + wrist_radius} 0 0" rpy="0 ${pi_2} 0"/> 
      <material name="black">
        <color rgba="0 0 0 1"/>
      </material>
    </visual>

    <inertial>
      <origin xyz="${(mic_stick_length / 2 ) + wrist_radius} 0 0" rpy="0 ${pi_2} 0"/>
      <mass value="${mic_stick_mass}"/>
      <inertia
        ixx="${(1.0/12.0) * mic_stick_mass * (3 * pow(mic_stick_radius, 2) + pow(mic_stick_length, 2))}"
        iyy="${(1.0/12.0) * mic_stick_mass * (3 * pow(mic_stick_radius, 2) + pow(mic_stick_length, 2))}"
        izz="${(1.0/2.0) * mic_stick_mass * pow(mic_stick_radius, 2)}"
        ixy="0.0"  ixz="0.0"  iyz="0.0"/>
    </inertial>
  </link>

  <joint name="mic_stick_joint" type="fixed">
    <parent link="mic_link"/>
    <child link="mic"/>
    <origin xyz="${mic_stick_length + wrist_radius + (2*mic_stick_radius)} 0 0" rpy="0 0 0"/>
  </joint>

  <link name="mic">
    <visual>
      <geometry>
        <sphere radius="${mic_stick_radius}"/>
      </geometry>
      <origin xyz="-${mic_stick_radius} 0 0" rpy="0 0 0"/> 
      <material name="black"/>
    </visual>

    <inertial>
      <origin xyz="-${mic_stick_radius} 0 0" rpy="0 0 0"/>
      <mass value="${mic_stick_mass}"/>
      <inertia
        ixx="${(2.0/5.0) * mic_mass * pow(mic_stick_radius, 2)}"
        iyy="${(2.0/5.0) * mic_mass * pow(mic_stick_radius, 2)}"
        izz="${(2.0/5.0) * mic_mass * pow(mic_stick_radius, 2)}"
        ixy="0.0"  ixz="0.0"  iyz="0.0"/>
    </inertial>
  </link>

</robot>